<?xml version="1.0" ?>
<!-- =================================================================================== -->
<!-- |    This document was autogenerated by xacro from spotmicroean.urdf.xacro        | -->
<!-- |    EDITING THIS FILE BY HAND IS NOT RECOMMENDED                                 | -->
<!-- =================================================================================== -->
<robot name="SpotMicroAI">
  <material name="red">
    <color rgba="1.0 0.0 0.0 1"/>
  </material>
  <material name="black">
    <color rgba="0.1 0.1 0.1 1"/>
  </material>
  <material name="grey">
    <color rgba="0.6 0.6 0.6 1"/>
  </material>
  <!-- Params -->
  <!-- Macros -->
  <!-- Robot Body -->
  <link name="base_link">
    <visual>
      <geometry>
        <mesh filename="../meshes/stl_ean/STL/Base.STL" scale="0.001 0.001 0.001"/>
      </geometry>
      <material name="red"/>
      <origin rpy="0 0 -1.5707" xyz="-0.135 0.055 -0.032"/>
    </visual>
    <collision>
      <geometry>
        <box size="0.2 0.11 0.07"/>
      </geometry>
      <origin rpy="0 0 0" xyz="0 0 0"/>
    </collision>
    <inertial>
      <mass value="0.94447"/>
      <inertia ixx="0.00387805268" ixy="-0.00003434884" ixz="-0.0000169616" iyy="0.00109473849" iyz="0.00031562911" izz="0.00409615181"/>
    </inertial>
  </link>
  <link name="rear_link">
    <visual>
      <geometry>
        <mesh filename="../meshes/stl_ean/STL/bottom.STL" scale="0.001 0.001 0.001"/>
      </geometry>
      <origin rpy="0 0 -1.5707" xyz="-0.105 0.055 -0.034"/>
      <material name="black"/>
    </visual>
    <collision>
      <geometry>
        <box size="0.057 0.11 0.07"/>
      </geometry>
      <origin rpy="0 0 0" xyz="0.135 0 0"/>
    </collision>
    <inertial>
      <mass value="0.13415"/>
      <inertia ixx="0.00232587491" ixy="0.00000216754" ixz="-0.00000449969" iyy="0.00028517681" iyz="0.00020709387" izz="0.00238553813"/>
    </inertial>
  </link>
  <joint name="base_rear" type="fixed">
    <parent link="base_link"/>
    <child link="rear_link"/>
  </joint>
  <link name="front_link">
    <visual>
      <geometry>
        <mesh filename="../meshes/stl_ean/STL/top.STL" scale="0.001 0.001 0.001"/>
      </geometry>
      <origin rpy="0 0 -1.5707" xyz="-0.185 0.065 -0.033"/>
      <material name="black"/>
    </visual>
    <collision>
      <geometry>
        <box size="0.058 0.11 0.07"/>
      </geometry>
      <origin rpy="0 0 0" xyz="-0.145 0 0"/>
    </collision>
    <inertial>
      <mass value="0.71111"/>
      <inertia ixx="0.01411887885" ixy="0.00503508247" ixz="0.00329443443" iyy="0.00738644691" iyz="0.0057782151" izz="0.01388095362"/>
    </inertial>
  </link>
  <joint name="base_front" type="fixed">
    <parent link="base_link"/>
    <child link="front_link"/>
  </joint>
  <!-- create Legs -->
  <link name="front_left_shoulder_link">
    <visual>
      <geometry>
        <mesh filename="../meshes/stl_ean/STL/left_fordward_right_backward_shoulder.STL" scale="0.001 0.001 0.001"/>
      </geometry>
      <origin rpy="-1.5707 3.1416 0" xyz="0.028 -0.03 -0.029"/>
      <material name="red"/>
    </visual>
    <collision>
      <geometry>
        <box size="0.044 0.038 0.07"/>
      </geometry>
      <origin rpy="0 0 0" xyz="0 0 0"/>
    </collision>
    <inertial>
      <mass value="0.11427"/>
      <inertia ixx="0.00003172169" ixy="-0.00000014527" ixz="0.00000432731" iyy="0.00005316718" iyz="-0.000000500" izz="0.00006588791"/>
    </inertial>
  </link>
  <link name="front_left_leg_link">
    <visual>
      <geometry>
        <mesh filename="../meshes/stl_ean/STL/left_arm.STL" scale="0.001 0.001 0.001"/>
      </geometry>
      <origin rpy="3.1416 -1.8 0" xyz="-0.02 0.025 -0.132"/>
      <material name="red"/>
    </visual>
    <collision>
      <origin rpy="0.0 0.0 0.0" xyz="0.0 0.0 -0.050"/>
      <geometry>
        <box size="0.028 0.036 0.12"/>
      </geometry>
    </collision>
    <inertial>
      <mass value="0.1942"/>
      <inertia ixx="0.00020999903" ixy="0.00033247456" ixz="0.0002163401" iyy="0.00136287772" iyz="0.00006388282" izz="0.00146174584"/>
    </inertial>
  </link>
  <link name="front_left_foot_link">
    <visual>
      <geometry>
        <mesh filename="../meshes/stl_ean/STL/left_wrist.STL" scale="0.001 0.001 0.001"/>
      </geometry>
      <origin rpy="1.5708 -1.5708 0" xyz="0.023 0.018 -.133"/>
      <material name="black"/>
    </visual>
    <collision>
      <geometry>
        <box size="0.026 0.020 0.115"/>
      </geometry>
      <origin rpy="0.0 0.0 0.0" xyz="0.0 0.0 -0.050"/>
    </collision>
    <inertial>
      <mass value="0.1452"/>
      <inertia ixx="0.00007223092" ixy="0.00001951089" ixz="0.00001265811" iyy="0.00027840078" iyz="0.00002203829" izz="0.00028998349"/>
    </inertial>
  </link>
  <link name="front_left_toe_link">
    <visual>
      <geometry>
        <mesh filename="../meshes/stl_ean/STL/Foot_Tip.STL" scale="0.001 0.001 0.001"/>
      </geometry>
      <origin rpy="0 2.35 0" xyz="0.00 0 0"/>
      <material name="grey"/>
    </visual>
    <collision>
      <geometry>
        <sphere radius="0.02"/>
      </geometry>
      <origin rpy="0 0 0" xyz="0 0 0"/>
      <contact_coefficients mu="1.1"/>
    </collision>
    <inertial>
      <mass value="0.0"/>
      <inertia ixx="0.0" ixy="0.0" ixz="0.0" iyy="0.0" iyz="0.0" izz="0.0"/>
    </inertial>
  </link>
  <joint name="joint_front_left_shoulder" type="revolute">
    <parent link="base_link"/>
    <child link="front_left_shoulder_link"/>
    <axis xyz="1 0 0"/>
    <origin rpy="0 0 0" xyz="-0.104 -0.038 0"/>
    <limit effort="1000.0" lower="-0.548" upper="0.548" velocity="0.7"/>
    <dynamics damping="0.0" friction="0.5"/>
  </joint>
  <joint name="joint_front_left_leg" type="revolute">
    <parent link="front_left_shoulder_link"/>
    <child link="front_left_leg_link"/>
    <axis xyz="0 1 0"/>
    <origin rpy="0 0 0" xyz="0 -0.052 0"/>
    <limit effort="1000.0" lower="-2.666" upper="1.548" velocity="0.5"/>
    <dynamics damping="0.0" friction="0.0"/>
  </joint>
  <joint name="joint_front_left_foot" type="revolute">
    <parent link="front_left_leg_link"/>
    <child link="front_left_foot_link"/>
    <axis xyz="0 1 0"/>
    <origin rpy="0 0 0" xyz="-0.01 0 -0.12"/>
    <limit effort="1000.0" lower="-0.1" upper="2.59" velocity="0.5"/>
    <dynamics damping="0.0" friction="0.5"/>
  </joint>
  <joint name="joint_front_left_toe" type="fixed">
    <parent link="front_left_foot_link"/>
    <child link="front_left_toe_link"/>
    <origin xyz="0 0 -0.115"/>
  </joint>
  <link name="front_right_shoulder_link">
    <visual>
      <geometry>
        <mesh filename="../meshes/stl_ean/STL/right_fordward_left_backward_shoulder.STL" scale="0.001 0.001 0.001"/>
      </geometry>
      <origin rpy="1.5707 0 0" xyz="-0.028 0.03 -0.027"/>
      <material name="red"/>
    </visual>
    <collision>
      <geometry>
        <box size="0.044 0.038 0.07"/>
      </geometry>
      <origin rpy="0 0 0" xyz="0 0 0"/>
    </collision>
    <inertial>
      <mass value="0.11427"/>
      <inertia ixx="0.00004878868" ixy="-0.0000003775" ixz="-0.00000017136" iyy="0.00004225848" iyz="-0.000000434" izz="0.00003791423"/>
    </inertial>
  </link>
  <link name="front_right_leg_link">
    <visual>
      <geometry>
        <mesh filename="../meshes/stl_ean/STL/right_arm.STL" scale="0.001 0.001 0.001"/>
      </geometry>
      <origin rpy="3.1416 -1.8 0" xyz="-0.02 0.039 -0.132"/>
      <material name="red"/>
    </visual>
    <collision>
      <origin rpy="0.0 0.0 0.0" xyz="0.0 0.0 -0.050"/>
      <geometry>
        <box size="0.028 0.036 0.12"/>
      </geometry>
    </collision>
    <inertial>
      <mass value="0.19412"/>
      <inertia ixx="0.00010075846" ixy="0.00001174271" ixz="0.00002227477" iyy="0.00028245225" iyz="-0.00000610061" izz="0.00027215429"/>
    </inertial>
  </link>
  <link name="front_right_foot_link">
    <visual>
      <geometry>
        <mesh filename="../meshes/stl_ean/STL/right_wrist.STL" scale="0.001 0.001 0.001"/>
      </geometry>
      <origin rpy="-1.5708 -1.5708 0" xyz="-0.013 -0.018 -.133"/>
      <material name="black"/>
    </visual>
    <collision>
      <geometry>
        <box size="0.026 0.020 0.115"/>
      </geometry>
      <origin rpy="0.0 0.0 0.0" xyz="0.0 0.0 -0.050"/>
    </collision>
    <inertial>
      <mass value="0.14521"/>
      <inertia ixx="0.00003908063" ixy="-0.00000081436" ixz="0.00003886203" iyy="0.0003689475" iyz="-0.00000004347" izz="0.00034737965"/>
    </inertial>
  </link>
  <link name="front_right_toe_link">
    <visual>
      <geometry>
        <mesh filename="../meshes/stl_ean/STL/Foot_Tip.STL" scale="0.001 0.001 0.001"/>
      </geometry>
      <origin rpy="0 2.35 0" xyz="0.00 0 0"/>
      <material name="grey"/>
    </visual>
    <collision>
      <geometry>
        <sphere radius="0.02"/>
      </geometry>
      <origin rpy="0 0 0" xyz="0 0 0"/>
      <contact_coefficients mu="1.1"/>
    </collision>
    <inertial>
      <mass value="0.0"/>
      <inertia ixx="0.0" ixy="0.0" ixz="0.0" iyy="0.0" iyz="0.0" izz="0.0"/>
    </inertial>
  </link>
  <joint name="joint_front_right_shoulder" type="revolute">
    <parent link="base_link"/>
    <child link="front_right_shoulder_link"/>
    <axis xyz="1 0 0"/>
    <origin rpy="0 0 0" xyz="-0.104 0.038 0"/>
    <limit effort="1000.0" lower="-0.548" upper="0.548" velocity="0.7"/>
    <dynamics damping="0.0" friction="0.5"/>
  </joint>
  <joint name="joint_front_right_leg" type="revolute">
    <parent link="front_right_shoulder_link"/>
    <child link="front_right_leg_link"/>
    <axis xyz="0 1 0"/>
    <origin rpy="0 0 0" xyz="0 0.052 0"/>
    <limit effort="1000.0" lower="-2.666" upper="1.548" velocity="0.5"/>
    <dynamics damping="0.0" friction="0.0"/>
  </joint>
  <joint name="joint_front_right_foot" type="revolute">
    <parent link="front_right_leg_link"/>
    <child link="front_right_foot_link"/>
    <axis xyz="0 1 0"/>
    <origin rpy="0 0 0" xyz="-0.01 0 -0.12"/>
    <limit effort="1000.0" lower="-0.1" upper="2.59" velocity="0.5"/>
    <dynamics damping="0.0" friction="0.5"/>
  </joint>
  <joint name="joint_front_right_toe" type="fixed">
    <parent link="front_right_foot_link"/>
    <child link="front_right_toe_link"/>
    <origin xyz="0 0 -0.115"/>
  </joint>
  <link name="rear_left_shoulder_link">
    <visual>
      <geometry>
        <mesh filename="../meshes/stl_ean/STL/left_fordward_right_backward_shoulder.STL" scale="0.001 0.001 0.001"/>
      </geometry>
      <origin rpy="-1.5707 3.1416 0" xyz="0.028 -0.03 -0.029"/>
      <material name="red"/>
    </visual>
    <collision>
      <geometry>
        <box size="0.044 0.038 0.07"/>
      </geometry>
      <origin rpy="0 0 0" xyz="0 0 0"/>
    </collision>
    <inertial>
      <mass value="0.11427"/>
      <inertia ixx="0.00003172169" ixy="-0.00000014527" ixz="0.00000432731" iyy="0.00005316718" iyz="-0.000000500" izz="0.00006588791"/>
    </inertial>
  </link>
  <link name="rear_left_leg_link">
    <visual>
      <geometry>
        <mesh filename="../meshes/stl_ean/STL/left_arm.STL" scale="0.001 0.001 0.001"/>
      </geometry>
      <origin rpy="3.1416 -1.8 0" xyz="-0.02 0.025 -0.132"/>
      <material name="red"/>
    </visual>
    <collision>
      <origin rpy="0.0 0.0 0.0" xyz="0.0 0.0 -0.050"/>
      <geometry>
        <box size="0.028 0.036 0.12"/>
      </geometry>
    </collision>
    <inertial>
      <mass value="0.1942"/>
      <inertia ixx="0.00020999903" ixy="0.00033247456" ixz="0.0002163401" iyy="0.00136287772" iyz="0.00006388282" izz="0.00146174584"/>
    </inertial>
  </link>
  <link name="rear_left_foot_link">
    <visual>
      <geometry>
        <mesh filename="../meshes/stl_ean/STL/left_wrist.STL" scale="0.001 0.001 0.001"/>
      </geometry>
      <origin rpy="1.5708 -1.5708 0" xyz="0.023 0.018 -.133"/>
      <material name="black"/>
    </visual>
    <collision>
      <geometry>
        <box size="0.026 0.020 0.115"/>
      </geometry>
      <origin rpy="0.0 0.0 0.0" xyz="0.0 0.0 -0.050"/>
    </collision>
    <inertial>
      <mass value="0.1452"/>
      <inertia ixx="0.00007223092" ixy="0.00001951089" ixz="0.00001265811" iyy="0.00027840078" iyz="0.00002203829" izz="0.00028998349"/>
    </inertial>
  </link>
  <link name="rear_left_toe_link">
    <visual>
      <geometry>
        <mesh filename="../meshes/stl_ean/STL/Foot_Tip.STL" scale="0.001 0.001 0.001"/>
      </geometry>
      <origin rpy="0 2.35 0" xyz="0.00 0 0"/>
      <material name="grey"/>
    </visual>
    <collision>
      <geometry>
        <sphere radius="0.02"/>
      </geometry>
      <origin rpy="0 0 0" xyz="0 0 0"/>
      <contact_coefficients mu="1.1"/>
    </collision>
    <inertial>
      <mass value="0.0"/>
      <inertia ixx="0.0" ixy="0.0" ixz="0.0" iyy="0.0" iyz="0.0" izz="0.0"/>
    </inertial>
  </link>
  <joint name="joint_rear_left_shoulder" type="revolute">
    <parent link="base_link"/>
    <child link="rear_left_shoulder_link"/>
    <axis xyz="1 0 0"/>
    <origin rpy="0 0 0" xyz="0.104 -0.038 0"/>
    <limit effort="1000.0" lower="-0.548" upper="0.548" velocity="0.7"/>
    <dynamics damping="0.0" friction="0.5"/>
  </joint>
  <joint name="joint_rear_left_leg" type="revolute">
    <parent link="rear_left_shoulder_link"/>
    <child link="rear_left_leg_link"/>
    <axis xyz="0 1 0"/>
    <origin rpy="0 0 0" xyz="0 -0.052 0"/>
    <limit effort="1000.0" lower="-2.666" upper="1.548" velocity="0.5"/>
    <dynamics damping="0.0" friction="0.0"/>
  </joint>
  <joint name="joint_rear_left_foot" type="revolute">
    <parent link="rear_left_leg_link"/>
    <child link="rear_left_foot_link"/>
    <axis xyz="0 1 0"/>
    <origin rpy="0 0 0" xyz="-0.01 0 -0.12"/>
    <limit effort="1000.0" lower="-0.1" upper="2.59" velocity="0.5"/>
    <dynamics damping="0.0" friction="0.5"/>
  </joint>
  <joint name="joint_rear_left_toe" type="fixed">
    <parent link="rear_left_foot_link"/>
    <child link="rear_left_toe_link"/>
    <origin xyz="0 0 -0.115"/>
  </joint>
  <link name="rear_right_shoulder_link">
    <visual>
      <geometry>
        <mesh filename="../meshes/stl_ean/STL/right_fordward_left_backward_shoulder.STL" scale="0.001 0.001 0.001"/>
      </geometry>
      <origin rpy="1.5707 0 0" xyz="-0.028 0.03 -0.027"/>
      <material name="red"/>
    </visual>
    <collision>
      <geometry>
        <box size="0.044 0.038 0.07"/>
      </geometry>
      <origin rpy="0 0 0" xyz="0 0 0"/>
    </collision>
    <inertial>
      <mass value="0.11427"/>
      <inertia ixx="0.00004878868" ixy="-0.0000003775" ixz="-0.00000017136" iyy="0.00004225848" iyz="-0.000000434" izz="0.00003791423"/>
    </inertial>
  </link>
  <link name="rear_right_leg_link">
    <visual>
      <geometry>
        <mesh filename="../meshes/stl_ean/STL/right_arm.STL" scale="0.001 0.001 0.001"/>
      </geometry>
      <origin rpy="3.1416 -1.8 0" xyz="-0.02 0.039 -0.132"/>
      <material name="red"/>
    </visual>
    <collision>
      <origin rpy="0.0 0.0 0.0" xyz="0.0 0.0 -0.050"/>
      <geometry>
        <box size="0.028 0.036 0.12"/>
      </geometry>
    </collision>
    <inertial>
      <mass value="0.19412"/>
      <inertia ixx="0.00010075846" ixy="0.00001174271" ixz="0.00002227477" iyy="0.00028245225" iyz="-0.00000610061" izz="0.00027215429"/>
    </inertial>
  </link>
  <link name="rear_right_foot_link">
    <visual>
      <geometry>
        <mesh filename="../meshes/stl_ean/STL/right_wrist.STL" scale="0.001 0.001 0.001"/>
      </geometry>
      <origin rpy="-1.5708 -1.5708 0" xyz="-0.013 -0.018 -.133"/>
      <material name="black"/>
    </visual>
    <collision>
      <geometry>
        <box size="0.026 0.020 0.115"/>
      </geometry>
      <origin rpy="0.0 0.0 0.0" xyz="0.0 0.0 -0.050"/>
    </collision>
    <inertial>
      <mass value="0.14521"/>
      <inertia ixx="0.00003908063" ixy="-0.00000081436" ixz="0.00003886203" iyy="0.0003689475" iyz="-0.00000004347" izz="0.00034737965"/>
    </inertial>
  </link>
  <link name="rear_right_toe_link">
    <visual>
      <geometry>
        <mesh filename="../meshes/stl_ean/STL/Foot_Tip.STL" scale="0.001 0.001 0.001"/>
      </geometry>
      <origin rpy="0 2.35 0" xyz="0.00 0 0"/>
      <material name="grey"/>
    </visual>
    <collision>
      <geometry>
        <sphere radius="0.02"/>
      </geometry>
      <origin rpy="0 0 0" xyz="0 0 0"/>
      <contact_coefficients mu="1.1"/>
    </collision>
    <inertial>
      <mass value="0.0"/>
      <inertia ixx="0.0" ixy="0.0" ixz="0.0" iyy="0.0" iyz="0.0" izz="0.0"/>
    </inertial>
  </link>
  <joint name="joint_rear_right_shoulder" type="revolute">
    <parent link="base_link"/>
    <child link="rear_right_shoulder_link"/>
    <axis xyz="1 0 0"/>
    <origin rpy="0 0 0" xyz="0.104 0.038 0"/>
    <limit effort="1000.0" lower="-0.548" upper="0.548" velocity="0.7"/>
    <dynamics damping="0.0" friction="0.5"/>
  </joint>
  <joint name="joint_rear_right_leg" type="revolute">
    <parent link="rear_right_shoulder_link"/>
    <child link="rear_right_leg_link"/>
    <axis xyz="0 1 0"/>
    <origin rpy="0 0 0" xyz="0 0.052 0"/>
    <limit effort="1000.0" lower="-2.666" upper="1.548" velocity="0.5"/>
    <dynamics damping="0.0" friction="0.0"/>
  </joint>
  <joint name="joint_rear_right_foot" type="revolute">
    <parent link="rear_right_leg_link"/>
    <child link="rear_right_foot_link"/>
    <axis xyz="0 1 0"/>
    <origin rpy="0 0 0" xyz="-0.01 0 -0.12"/>
    <limit effort="1000.0" lower="-0.1" upper="2.59" velocity="0.5"/>
    <dynamics damping="0.0" friction="0.5"/>
  </joint>
  <joint name="joint_rear_right_toe" type="fixed">
    <parent link="rear_right_foot_link"/>
    <child link="rear_right_toe_link"/>
    <origin xyz="0 0 -0.115"/>
  </joint>
</robot>